<?xml version="1.0" ?>
<robot name="elbow">

	<material name="white">
		<color rgba="1.0 1.0 1.0 1.0"/>
	</material>
	<material name="red">
		<color rgba="1.0 0.2 0.2 1.0"/>
	</material>
	<material name="orange">
		<color rgba="1.0 0.423529411765 0.0392156862745 1.0"/>
	</material>

	<!-- Root World Link -->
	<link name="world"/>

	<!-- Ground -->
	<joint name="ground" type="fixed">
		<parent link="world"/>
		<child link="ground"/>
		<origin rpy="0.1 0. 0" xyz="0 0 -1"/>
	</joint>


	<link name="ground">
		<visual>
			<origin rpy="0. 0. 0" xyz="0 0 0"/>
			<geometry>
				<box size="100 100 2"/>
			</geometry>
			<material name="white"/>
		</visual>
		<collision>
			<origin rpy="0. 0. 0" xyz="0 0 0"/>
			<geometry>
				<box size="100 100 2"/>
			</geometry>
		</collision>
	</link>


	<!-- Actual elbow -->
	<joint name="freeFlyer" type="floating">
		<parent link="world"/>
		<child link="freeFlyer"/>
	</joint>

	<!-- root -->
	<link name="freeFlyer">
		<visual>
			<origin rpy="0 0 0" xyz="0 0 0"/>
			<geometry>
				<sphere radius=".3"/>
			</geometry>
			<material name="orange"/>
		</visual>
		<collision>
			<origin rpy="0 0 0" xyz="0 0 0"/>
			<geometry>
				<sphere radius=".3"/>
			</geometry>
		</collision>

		<inertial>
			<origin rpy="0 0 0" xyz="0 0 0"/>
			<mass value="1."/>
			<inertia ixx="0.04" ixy="0." ixz="0." iyy="0.04" iyz="0." izz="0.04"/>
		</inertial>
	</link>

	<joint name="ext" type="fixed">
		<parent link="freeFlyer"/>
		<child link="ext"/>
		<axis xyz="0 1 0" />
	</joint>

	<link name="ext">
		<visual>
			<origin rpy="0 0 0" xyz="-1 0 0"/>
			<geometry>
				<sphere radius=".3"/>
			</geometry>
			<material name="orange"/>
		</visual>
		<collision>
			<origin rpy="0 0 0" xyz="-1 0 0"/>
			<geometry>
				<sphere radius=".3"/>
			</geometry>
		</collision>

		<inertial>
			<origin rpy="0 0 0" xyz="-1 0 0"/>
			<mass value="1."/>
			<inertia ixx="0.04" ixy="0." ixz="0." iyy="0.04" iyz="0." izz="0.04"/>
		</inertial>
	</link>

	<joint name="arm" type="revolute">
		<parent link="freeFlyer"/>
		<child link="arm"/>
		<axis xyz="0 1 0" />
		<limit lower="-1" upper="1" effort="10000" velocity="10000"/>
	</joint>

	<link name="arm">
		<visual>
			<origin rpy="0 0 0" xyz="1 0 0"/>
			<geometry>
				<sphere radius=".3"/>
			</geometry>
			<material name="orange"/>
		</visual>
		<collision>
			<origin rpy="0 0 0" xyz="1 0 0"/>
			<geometry>
				<sphere radius=".3"/>
			</geometry>
		</collision>

		<inertial>
			<origin rpy="0 0 0" xyz="1 0 0"/>
			<mass value="1."/>
			<inertia ixx="0.04" ixy="0." ixz="0." iyy="0.04" iyz="0." izz="0.04"/>
		</inertial>
	</link>
</robot>