<?xml version="1.0" ?>
<robot name="idefX">
	<material name="black">
		<color rgba="0.0 0.0 0.0 1.0"/>
	</material>
	<material name="blue">
		<color rgba="0.0 0.0 0.8 1.0"/>
	</material>
	<material name="green">
		<color rgba="0.0 0.8 0.0 1.0"/>
	</material>
	<material name="grey">
		<color rgba="0.2 0.2 0.2 1.0"/>
	</material>
	<material name="silver">
		<color rgba="0.913725490196 0.913725490196 0.847058823529 1.0"/>
	</material>
	<material name="orange">
		<color rgba="1.0 0.423529411765 0.0392156862745 1.0"/>
	</material>
	<material name="brown">
		<color rgba="0.870588235294 0.811764705882 0.764705882353 1.0"/>
	</material>
	<material name="red">
		<color rgba="0.8 0.0 0.0 1.0"/>
	</material>
	<material name="white">
		<color rgba="1.0 1.0 1.0 1.0"/>
	</material>
	<link name="ground">
		<visual>
			<origin xyz="0 0 -1" rpy="0 0 0"/>
			<geometry>
				<box size="100 100 2"/>
			</geometry>
			<material name="white"/>
		</visual>
		<collision>
			<origin xyz="0 0 -1" rpy="0 0 0"/>
			<geometry>
				<box size="100 100 2"/>
			</geometry>
		</collision>
	</link>
	<link name="trunk">
		<visual>
			<origin xyz="0 0 0" rpy="0 0 0"/>
			<geometry>
				<mesh filename="../data/idefX/trunk.dae"/>
			</geometry>
		</visual>
		<inertial>
			<origin xyz="0 0 0" rpy="0 0 0"/>
			<mass value="7.5"/>
			<inertia ixx="0.05" ixy="0" ixz="0" iyy="0.05" iyz="0" izz="0.05"/>
		</inertial>
	</link>
	<joint name="trunk_joint" type="floating">
		<origin rpy="0 0 0" xyz="0 0 0"/>
		<parent link="ground"/>
		<child link="trunk"/>
	</joint>
	<joint name="FL_first_motor_joint" type="fixed">
		<origin rpy="0 0 0" xyz="0.15250000000000002 0.075 0.0"/>
		<parent link="trunk"/>
		<child link="FL_first_motor"/>
	</joint>
	<link name="FL_first_motor">
		<visual>
			<origin xyz="0 0 0" rpy="0 1.5707963267948966 0"/>
			<geometry>
				<sphere radius="0.03"/>
			</geometry>
			<material name="blue"/>
		</visual>
		<inertial>
			<origin xyz="0 0 0" rpy="0 1.5707963267948966 0"/>
			<mass value="0.7"/>
			<inertia ixx="0.00184" ixy="0" ixz="0" iyy="0.00184" iyz="0" izz="0.0035"/>
		</inertial>
	</link>
	<joint name="FL_clavicle_joint" type="revolute">
		<origin rpy="0 0 0" xyz="0.225 0.075 -0.0"/>
		<parent link="trunk"/>
		<child link="FL_clavicle"/>
		<axis xyz="1 0 0"/>
		<dynamics damping="0" friction="0"/>
		<limit effort="10000" velocity="100000"/>
	</joint>
	<link name="FL_clavicle">
		<visual>
			<origin xyz="0 0.0325 0" rpy="0 0 0"/>
			<geometry>
				<sphere radius="0.03"/>
			</geometry>
			<material name="blue"/>
		</visual>
		<inertial>
			<origin xyz="0 0.0325 0" rpy="0 0 0"/>
			<mass value="0.7"/>
			<inertia ixx="0.00184" ixy="0" ixz="0" iyy="0.00184" iyz="0" izz="0.0035"/>
		</inertial>
	</link>
	<joint name="FL_arm_joint" type="revolute">
		<origin rpy="0 0 0" xyz="0 0.07 0"/>
		<parent link="FL_clavicle"/>
		<child link="FL_arm"/>
		<axis xyz="0 1 0"/>
		<dynamics damping="0" friction="0"/>
		<limit effort="10000" velocity="100000"/>
	</joint>
	<link name="FL_arm">
		<visual>
			<origin xyz="0 0 -0.098" rpy="0 0 0"/>
			<geometry>
				<sphere radius="0.03"/>
			</geometry>
			<material name="blue"/>
		</visual>
		<inertial>
			<origin xyz="0 0 -0.098" rpy="0 0 0"/>
			<mass value="0.2"/>
			<inertia ixx="0.0002" ixy="0" ixz="0" iyy="0.0002" iyz="0" izz="8e-05"/>
		</inertial>
	</link>
	<joint name="FL_third_motor_joint" type="fixed">
		<origin rpy="0 0 0" xyz="0.0 0.037500000000000006 0.0"/>
		<parent link="FL_arm"/>
		<child link="FL_third_motor"/>
	</joint>
	<link name="FL_third_motor">
		<visual>
			<origin xyz="0 0 0" rpy="0 0 0"/>
			<geometry>
				<sphere radius="0.03"/>
			</geometry>
			<material name="blue"/>
		</visual>
		<inertial>
			<origin xyz="0 0 0" rpy="0 0 0"/>
			<mass value="0.7"/>
			<inertia ixx="0.00184" ixy="0" ixz="0" iyy="0.00184" iyz="0" izz="0.0035"/>
		</inertial>
	</link>
	<joint name="FL_forearm_joint" type="revolute">
		<origin rpy="0 0 0" xyz="0 0.01 -0.196"/>
		<parent link="FL_arm"/>
		<child link="FL_forearm"/>
		<axis xyz="0 1 0"/>
		<dynamics damping="0" friction="0"/>
		<limit effort="10000" velocity="100000"/>
	</joint>
	<link name="FL_forearm">
		<visual>
			<origin xyz="0 0 -0.1" rpy="0 0 0"/>
			<geometry>
				<sphere radius="0.03"/>
			</geometry>
			<material name="blue"/>
		</visual>
		<inertial>
			<origin xyz="0 0 -0.1" rpy="0 0 0"/>
			<mass value="0.1"/>
			<inertia ixx="0.0001" ixy="0" ixz="0" iyy="0.0001" iyz="0" izz="4e-05"/>
		</inertial>
	</link>
	<joint name="FL_foot_joint" type="fixed">
		<origin rpy="0 0 0" xyz="0 0 -0.2"/>
		<parent link="FL_forearm"/>
		<child link="FL_foot"/>
	</joint>
	<link name="FL_foot">
		<visual>
			<origin xyz="0 0 0" rpy="0 0 0"/>
			<geometry>
				<sphere radius="0.03"/>
			</geometry>
			<material name="blue"/>
		</visual>
		<inertial>
			<origin xyz="0 0 0" rpy="0 0 0"/>
			<mass value="0.01"/>
			<inertia ixx="6e-06" ixy="0" ixz="0" iyy="6e-06" iyz="0" izz="6e-06"/>
		</inertial>
	</link>
	<joint name="FR_first_motor_joint" type="fixed">
		<origin rpy="0 0 0" xyz="0.15250000000000002 -0.075 0.0"/>
		<parent link="trunk"/>
		<child link="FR_first_motor"/>
	</joint>
	<link name="FR_first_motor">
		<visual>
			<origin xyz="0 0 0" rpy="0 1.5707963267948966 0"/>
			<geometry>
				<sphere radius="0.03"/>
			</geometry>
			<material name="blue"/>
		</visual>
		<inertial>
			<origin xyz="0 0 0" rpy="0 1.5707963267948966 0"/>
			<mass value="0.7"/>
			<inertia ixx="0.00184" ixy="0" ixz="0" iyy="0.00184" iyz="0" izz="0.0035"/>
		</inertial>
	</link>
	<joint name="FR_clavicle_joint" type="revolute">
		<origin rpy="0 0 0" xyz="0.225 -0.075 -0.0"/>
		<parent link="trunk"/>
		<child link="FR_clavicle"/>
		<axis xyz="1 0 0"/>
		<dynamics damping="0" friction="0"/>
		<limit effort="10000" velocity="100000"/>
	</joint>
	<link name="FR_clavicle">
		<visual>
			<origin xyz="0 -0.0325 0" rpy="0 0 0"/>
			<geometry>
				<sphere radius="0.03"/>
			</geometry>
			<material name="blue"/>
		</visual>
		<inertial>
			<origin xyz="0 -0.0325 0" rpy="0 0 0"/>
			<mass value="0.7"/>
			<inertia ixx="0.00184" ixy="0" ixz="0" iyy="0.00184" iyz="0" izz="0.0035"/>
		</inertial>
	</link>
	<joint name="FR_arm_joint" type="revolute">
		<origin rpy="0 0 0" xyz="0 -0.07 0"/>
		<parent link="FR_clavicle"/>
		<child link="FR_arm"/>
		<axis xyz="0 1 0"/>
		<dynamics damping="0" friction="0"/>
		<limit effort="10000" velocity="100000"/>
	</joint>
	<link name="FR_arm">
		<visual>
			<origin xyz="0 0 -0.098" rpy="0 0 0"/>
			<geometry>
				<sphere radius="0.03"/>
			</geometry>
			<material name="blue"/>
		</visual>
		<inertial>
			<origin xyz="0 0 -0.098" rpy="0 0 0"/>
			<mass value="0.2"/>
			<inertia ixx="0.0002" ixy="0" ixz="0" iyy="0.0002" iyz="0" izz="8e-05"/>
		</inertial>
	</link>
	<joint name="FR_third_motor_joint" type="fixed">
		<origin rpy="0 0 0" xyz="0.0 -0.037500000000000006 0.0"/>
		<parent link="FR_arm"/>
		<child link="FR_third_motor"/>
	</joint>
	<link name="FR_third_motor">
		<visual>
			<origin xyz="0 0 0" rpy="0 0 0"/>
			<geometry>
				<sphere radius="0.03"/>
			</geometry>
			<material name="blue"/>
		</visual>
		<inertial>
			<origin xyz="0 0 0" rpy="0 0 0"/>
			<mass value="0.7"/>
			<inertia ixx="0.00184" ixy="0" ixz="0" iyy="0.00184" iyz="0" izz="0.0035"/>
		</inertial>
	</link>
	<joint name="FR_forearm_joint" type="revolute">
		<origin rpy="0 0 0" xyz="0 -0.01 -0.196"/>
		<parent link="FR_arm"/>
		<child link="FR_forearm"/>
		<axis xyz="0 1 0"/>
		<dynamics damping="0" friction="0"/>
		<limit effort="10000" velocity="100000"/>
	</joint>
	<link name="FR_forearm">
		<visual>
			<origin xyz="0 0 -0.1" rpy="0 0 0"/>
			<geometry>
				<sphere radius="0.03"/>
			</geometry>
			<material name="blue"/>
		</visual>
		<inertial>
			<origin xyz="0 0 -0.1" rpy="0 0 0"/>
			<mass value="0.1"/>
			<inertia ixx="0.0001" ixy="0" ixz="0" iyy="0.0001" iyz="0" izz="4e-05"/>
		</inertial>
	</link>
	<joint name="FR_foot_joint" type="fixed">
		<origin rpy="0 0 0" xyz="0 0 -0.2"/>
		<parent link="FR_forearm"/>
		<child link="FR_foot"/>
	</joint>
	<link name="FR_foot">
		<visual>
			<origin xyz="0 0 0" rpy="0 0 0"/>
			<geometry>
				<sphere radius="0.03"/>
			</geometry>
			<material name="blue"/>
		</visual>
		<inertial>
			<origin xyz="0 0 0" rpy="0 0 0"/>
			<mass value="0.01"/>
			<inertia ixx="6e-06" ixy="0" ixz="0" iyy="6e-06" iyz="0" izz="6e-06"/>
		</inertial>
	</link>
	<joint name="BL_first_motor_joint" type="fixed">
		<origin rpy="0 0 0" xyz="-0.15250000000000002 0.075 0.0"/>
		<parent link="trunk"/>
		<child link="BL_first_motor"/>
	</joint>
	<link name="BL_first_motor">
		<visual>
			<origin xyz="0 0 0" rpy="0 1.5707963267948966 0"/>
			<geometry>
				<sphere radius="0.03"/>
			</geometry>
			<material name="blue"/>
		</visual>
		<inertial>
			<origin xyz="0 0 0" rpy="0 1.5707963267948966 0"/>
			<mass value="0.7"/>
			<inertia ixx="0.00184" ixy="0" ixz="0" iyy="0.00184" iyz="0" izz="0.0035"/>
		</inertial>
	</link>
	<joint name="BL_clavicle_joint" type="revolute">
		<origin rpy="0 0 0" xyz="-0.225 0.075 -0.0"/>
		<parent link="trunk"/>
		<child link="BL_clavicle"/>
		<axis xyz="1 0 0"/>
		<dynamics damping="0" friction="0"/>
		<limit effort="10000" velocity="100000"/>
	</joint>
	<link name="BL_clavicle">
		<visual>
			<origin xyz="0 0.0325 0" rpy="0 0 0"/>
			<geometry>
				<sphere radius="0.03"/>
			</geometry>
			<material name="blue"/>
		</visual>
		<inertial>
			<origin xyz="0 0.0325 0" rpy="0 0 0"/>
			<mass value="0.7"/>
			<inertia ixx="0.00184" ixy="0" ixz="0" iyy="0.00184" iyz="0" izz="0.0035"/>
		</inertial>
	</link>
	<joint name="BL_arm_joint" type="revolute">
		<origin rpy="0 0 0" xyz="0 0.07 0"/>
		<parent link="BL_clavicle"/>
		<child link="BL_arm"/>
		<axis xyz="0 1 0"/>
		<dynamics damping="0" friction="0"/>
		<limit effort="10000" velocity="100000"/>
	</joint>
	<link name="BL_arm">
		<visual>
			<origin xyz="0 0 -0.098" rpy="0 0 0"/>
			<geometry>
				<sphere radius="0.03"/>
			</geometry>
			<material name="blue"/>
		</visual>
		<inertial>
			<origin xyz="0 0 -0.098" rpy="0 0 0"/>
			<mass value="0.2"/>
			<inertia ixx="0.0002" ixy="0" ixz="0" iyy="0.0002" iyz="0" izz="8e-05"/>
		</inertial>
	</link>
	<joint name="BL_third_motor_joint" type="fixed">
		<origin rpy="0 0 0" xyz="0.0 0.037500000000000006 0.0"/>
		<parent link="BL_arm"/>
		<child link="BL_third_motor"/>
	</joint>
	<link name="BL_third_motor">
		<visual>
			<origin xyz="0 0 0" rpy="0 0 0"/>
			<geometry>
				<sphere radius="0.03"/>
			</geometry>
			<material name="blue"/>
		</visual>
		<inertial>
			<origin xyz="0 0 0" rpy="0 0 0"/>
			<mass value="0.7"/>
			<inertia ixx="0.00184" ixy="0" ixz="0" iyy="0.00184" iyz="0" izz="0.0035"/>
		</inertial>
	</link>
	<joint name="BL_forearm_joint" type="revolute">
		<origin rpy="0 0 0" xyz="0 0.01 -0.196"/>
		<parent link="BL_arm"/>
		<child link="BL_forearm"/>
		<axis xyz="0 1 0"/>
		<dynamics damping="0" friction="0"/>
		<limit effort="10000" velocity="100000"/>
	</joint>
	<link name="BL_forearm">
		<visual>
			<origin xyz="0 0 -0.1" rpy="0 0 0"/>
			<geometry>
				<sphere radius="0.03"/>
			</geometry>
			<material name="blue"/>
		</visual>
		<inertial>
			<origin xyz="0 0 -0.1" rpy="0 0 0"/>
			<mass value="0.1"/>
			<inertia ixx="0.0001" ixy="0" ixz="0" iyy="0.0001" iyz="0" izz="4e-05"/>
		</inertial>
	</link>
	<joint name="BL_foot_joint" type="fixed">
		<origin rpy="0 0 0" xyz="0 0 -0.2"/>
		<parent link="BL_forearm"/>
		<child link="BL_foot"/>
	</joint>
	<link name="BL_foot">
		<visual>
			<origin xyz="0 0 0" rpy="0 0 0"/>
			<geometry>
				<sphere radius="0.03"/>
			</geometry>
			<material name="blue"/>
		</visual>
		<inertial>
			<origin xyz="0 0 0" rpy="0 0 0"/>
			<mass value="0.01"/>
			<inertia ixx="6e-06" ixy="0" ixz="0" iyy="6e-06" iyz="0" izz="6e-06"/>
		</inertial>
	</link>
	<joint name="BR_first_motor_joint" type="fixed">
		<origin rpy="0 0 0" xyz="-0.15250000000000002 -0.075 0.0"/>
		<parent link="trunk"/>
		<child link="BR_first_motor"/>
	</joint>
	<link name="BR_first_motor">
		<visual>
			<origin xyz="0 0 0" rpy="0 1.5707963267948966 0"/>
			<geometry>
				<sphere radius="0.03"/>
			</geometry>
			<material name="blue"/>
		</visual>
		<inertial>
			<origin xyz="0 0 0" rpy="0 1.5707963267948966 0"/>
			<mass value="0.7"/>
			<inertia ixx="0.00184" ixy="0" ixz="0" iyy="0.00184" iyz="0" izz="0.0035"/>
		</inertial>
	</link>
	<joint name="BR_clavicle_joint" type="revolute">
		<origin rpy="0 0 0" xyz="-0.225 -0.075 -0.0"/>
		<parent link="trunk"/>
		<child link="BR_clavicle"/>
		<axis xyz="1 0 0"/>
		<dynamics damping="0" friction="0"/>
		<limit effort="10000" velocity="100000"/>
	</joint>
	<link name="BR_clavicle">
		<visual>
			<origin xyz="0 -0.0325 0" rpy="0 0 0"/>
			<geometry>
				<sphere radius="0.03"/>
			</geometry>
			<material name="blue"/>
		</visual>
		<inertial>
			<origin xyz="0 -0.0325 0" rpy="0 0 0"/>
			<mass value="0.7"/>
			<inertia ixx="0.00184" ixy="0" ixz="0" iyy="0.00184" iyz="0" izz="0.0035"/>
		</inertial>
	</link>
	<joint name="BR_arm_joint" type="revolute">
		<origin rpy="0 0 0" xyz="0 -0.07 0"/>
		<parent link="BR_clavicle"/>
		<child link="BR_arm"/>
		<axis xyz="0 1 0"/>
		<dynamics damping="0" friction="0"/>
		<limit effort="10000" velocity="100000"/>
	</joint>
	<link name="BR_arm">
		<visual>
			<origin xyz="0 0 -0.098" rpy="0 0 0"/>
			<geometry>
				<sphere radius="0.03"/>
			</geometry>
			<material name="blue"/>
		</visual>
		<inertial>
			<origin xyz="0 0 -0.098" rpy="0 0 0"/>
			<mass value="0.2"/>
			<inertia ixx="0.0002" ixy="0" ixz="0" iyy="0.0002" iyz="0" izz="8e-05"/>
		</inertial>
	</link>
	<joint name="BR_third_motor_joint" type="fixed">
		<origin rpy="0 0 0" xyz="0.0 -0.037500000000000006 0.0"/>
		<parent link="BR_arm"/>
		<child link="BR_third_motor"/>
	</joint>
	<link name="BR_third_motor">
		<visual>
			<origin xyz="0 0 0" rpy="0 0 0"/>
			<geometry>
				<sphere radius="0.03"/>
			</geometry>
			<material name="blue"/>
		</visual>
		<inertial>
			<origin xyz="0 0 0" rpy="0 0 0"/>
			<mass value="0.7"/>
			<inertia ixx="0.00184" ixy="0" ixz="0" iyy="0.00184" iyz="0" izz="0.0035"/>
		</inertial>
	</link>
	<joint name="BR_forearm_joint" type="revolute">
		<origin rpy="0 0 0" xyz="0 -0.01 -0.196"/>
		<parent link="BR_arm"/>
		<child link="BR_forearm"/>
		<axis xyz="0 1 0"/>
		<dynamics damping="0" friction="0"/>
		<limit effort="10000" velocity="100000"/>
	</joint>
	<link name="BR_forearm">
		<visual>
			<origin xyz="0 0 -0.1" rpy="0 0 0"/>
			<geometry>
				<sphere radius="0.03"/>
			</geometry>
			<material name="blue"/>
		</visual>
		<inertial>
			<origin xyz="0 0 -0.1" rpy="0 0 0"/>
			<mass value="0.1"/>
			<inertia ixx="0.0001" ixy="0" ixz="0" iyy="0.0001" iyz="0" izz="4e-05"/>
		</inertial>
	</link>
	<joint name="BR_foot_joint" type="fixed">
		<origin rpy="0 0 0" xyz="0 0 -0.2"/>
		<parent link="BR_forearm"/>
		<child link="BR_foot"/>
	</joint>
	<link name="BR_foot">
		<visual>
			<origin xyz="0 0 0" rpy="0 0 0"/>
			<geometry>
				<sphere radius="0.03"/>
			</geometry>
			<material name="blue"/>
		</visual>
		<inertial>
			<origin xyz="0 0 0" rpy="0 0 0"/>
			<mass value="0.01"/>
			<inertia ixx="6e-06" ixy="0" ixz="0" iyy="6e-06" iyz="0" izz="6e-06"/>
		</inertial>
	</link>
</robot>
