<?xml version="1.0" ?>
<robot name="ball">

	<material name="white">
		<color rgba="1.0 1.0 1.0 1.0"/>
	</material>
	<material name="orange">
		<color rgba="1.0 0.423529411765 0.0392156862745 1.0"/>
	</material>

	<!-- Root World Link -->
	<link name="world"/>

	<!-- Ground -->
	<joint name="ground" type="fixed">
		<parent link="world"/>
		<child link="ground"/>
	</joint>


	<link name="ground">
		<visual>
			<origin rpy="0.1 0 0" xyz="0 0 -1"/>
			<geometry>
				<box size="100 100 2"/>
			</geometry>
			<material name="white"/>
		</visual>
		<collision>
			<origin rpy="0.1 0 0" xyz="0 0 -1"/>
			<geometry>
				<box size="100 100 2"/>
			</geometry>
		</collision>
	</link>


	<!-- Actual ball -->
	<joint name="freeFlyer" type="floating">
		<parent link="world"/>
		<child link="freeFlyer"/>
	</joint>


	<link name="freeFlyer">
		<visual>
			<origin rpy="0 0 0" xyz="0 0 0"/>
			<geometry>
				<sphere radius="1.0"/>
			</geometry>
			<material name="orange"/>
		</visual>
		<collision>
			<origin rpy="0 0 0" xyz="0 0 0"/>
			<geometry>
				<sphere radius="1.0"/>
			</geometry>
		</collision>

		<inertial>
			<origin rpy="0 0 0" xyz="0 0 0"/>
			<mass value="1."/>
			<inertia ixx="0.4" ixy="0." ixz="0." iyy="0.4" iyz="0." izz="0.4"/>
		</inertial>
	</link>

</robot>